Workbook

Sheet Power Calculation
B2: Page 1/7 | J2: POWER CALCULATION | Q2: Project: | S2: =getfilename() -> #NAME?
Q3: Systems by:
Q4: Print date: | S4: =TODAY() -> 46140
D6: Name | E6: What | F6: Amount | G6: Wattage | H6: Total Amp | I6: Line Load | J6: Circuit Load | K6: % Load | O6: Name | P6: What | Q6: Amount | R6: Wattage | S6: Total Amp | T6: Line Load | U6: Circuit Load | V6: % Load
B7: HOT 1 | C7: 1 | D7: Wash | E7: R1 BeamWash | F7: 8 | G7: =IFERROR(VLOOKUP(E7, 'Unit Database'!$C$5:$D$212, 2, 0), 0) -> 284 | H7: =(IFERROR(VLOOKUP(E7, 'Unit Database'!$C$5:$E$212, 3, 0), 0)*F7) -> 9.84 | I7: =F7*G7 -> 2272 | J7: =SUM(I7:I9) -> 2272 | K7: =J7/3680 -> 0.6173913 | M7: HOT 2 | N7: 1 | R7: =IFERROR(VLOOKUP(P7, 'Unit Database'!$C$5:$D$212, 2, 0), 0) -> 0 | S7: =(IFERROR(VLOOKUP(P7, 'Unit Database'!$C$5:$E$212, 3, 0), 0)*Q7) -> 0 | T7: =Q7*R7 -> 0 | U7: =SUM(T7:T9) -> 0 | V7: =U7/3680 -> 0
D8: Blinds | F8: 5 | G8: =IFERROR(VLOOKUP(E8, 'Unit Database'!$C$5:$D$212, 2, 0), 0) -> 0 | H8: =(IFERROR(VLOOKUP(E8, 'Unit Database'!$C$5:$E$212, 3, 0), 0)*F8) -> 0 | I8: =F8*G8 -> 0 | R8: =IFERROR(VLOOKUP(P8, 'Unit Database'!$C$5:$D$212, 2, 0), 0) -> 0 | S8: =(IFERROR(VLOOKUP(P8, 'Unit Database'!$C$5:$E$212, 3, 0), 0)*Q8) -> 0 | T8: =Q8*R8 -> 0
G9: =IFERROR(VLOOKUP(E9, 'Unit Database'!$C$5:$D$212, 2, 0), 0) -> 0 | H9: =(IFERROR(VLOOKUP(E9, 'Unit Database'!$C$5:$E$212, 3, 0), 0)*F9) -> 0 | I9: =F9*G9 -> 0 | R9: =IFERROR(VLOOKUP(P9, 'Unit Database'!$C$5:$D$212, 2, 0), 0) -> 0 | S9: =(IFERROR(VLOOKUP(P9, 'Unit Database'!$C$5:$E$212, 3, 0), 0)*Q9) -> 0 | T9: =Q9*R9 -> 0
B10: Soca Name: | C10: 2 | D10: Spiss | E10: Diablo | F10: 4 | G10: =IFERROR(VLOOKUP(E10, 'Unit Database'!$C$5:$D$212, 2, 0), 0) -> 550 | H10: =(IFERROR(VLOOKUP(E10, 'Unit Database'!$C$5:$E$212, 3, 0), 0)*F10) -> 9.56 | I10: =F10*G10 -> 2200 | J10: =SUM(I10:I12) -> 2200 | K10: =J10/3680 -> 0.59782609 | M10: Soca Name: | N10: 2 | R10: =IFERROR(VLOOKUP(P10, 'Unit Database'!$C$5:$D$212, 2, 0), 0) -> 0 | S10: =(IFERROR(VLOOKUP(P10, 'Unit Database'!$C$5:$E$212, 3, 0), 0)*Q10) -> 0 | T10: =Q10*R10 -> 0 | U10: =SUM(T10:T12) -> 0 | V10: =U10/3680 -> 0
G11: =IFERROR(VLOOKUP(E11, 'Unit Database'!$C$5:$D$212, 2, 0), 0) -> 0 | H11: =(IFERROR(VLOOKUP(E11, 'Unit Database'!$C$5:$E$212, 3, 0), 0)*F11) -> 0 | I11: =F11*G11 -> 0 | R11: =IFERROR(VLOOKUP(P11, 'Unit Database'!$C$5:$D$212, 2, 0), 0) -> 0 | S11: =(IFERROR(VLOOKUP(P11, 'Unit Database'!$C$5:$E$212, 3, 0), 0)*Q11) -> 0 | T11: =Q11*R11 -> 0
G12: =IFERROR(VLOOKUP(E12, 'Unit Database'!$C$5:$D$212, 2, 0), 0) -> 0 | H12: =(IFERROR(VLOOKUP(E12, 'Unit Database'!$C$5:$E$212, 3, 0), 0)*F12) -> 0 | I12: =F12*G12 -> 0 | R12: =IFERROR(VLOOKUP(P12, 'Unit Database'!$C$5:$D$212, 2, 0), 0) -> 0 | S12: =(IFERROR(VLOOKUP(P12, 'Unit Database'!$C$5:$E$212, 3, 0), 0)*Q12) -> 0 | T12: =Q12*R12 -> 0
C13: 3 | D13: Front | E13: XBABY | F13: 4 | G13: =IFERROR(VLOOKUP(E13, 'Unit Database'!$C$5:$D$212, 2, 0), 0) -> 75 | H13: =(IFERROR(VLOOKUP(E13, 'Unit Database'!$C$5:$E$212, 3, 0), 0)*F13) -> 1.28 | I13: =F13*G13 -> 300 | J13: =SUM(I13:I15) -> 300 | K13: =J13/3680 -> 0.081521739 | N13: 3 | R13: =IFERROR(VLOOKUP(P13, 'Unit Database'!$C$5:$D$212, 2, 0), 0) -> 0 | S13: =(IFERROR(VLOOKUP(P13, 'Unit Database'!$C$5:$E$212, 3, 0), 0)*Q13) -> 0 | T13: =Q13*R13 -> 0 | U13: =SUM(T13:T15) -> 0 | V13: =U13/3680 -> 0
G14: =IFERROR(VLOOKUP(E14, 'Unit Database'!$C$5:$D$212, 2, 0), 0) -> 0 | H14: =(IFERROR(VLOOKUP(E14, 'Unit Database'!$C$5:$E$212, 3, 0), 0)*F14) -> 0 | I14: =F14*G14 -> 0 | R14: =IFERROR(VLOOKUP(P14, 'Unit Database'!$C$5:$D$212, 2, 0), 0) -> 0 | S14: =(IFERROR(VLOOKUP(P14, 'Unit Database'!$C$5:$E$212, 3, 0), 0)*Q14) -> 0 | T14: =Q14*R14 -> 0
B15: Input Power: | G15: =IFERROR(VLOOKUP(E15, 'Unit Database'!$C$5:$D$212, 2, 0), 0) -> 0 | H15: =(IFERROR(VLOOKUP(E15, 'Unit Database'!$C$5:$E$212, 3, 0), 0)*F15) -> 0 | I15: =F15*G15 -> 0 | M15: Input Power: | R15: =IFERROR(VLOOKUP(P15, 'Unit Database'!$C$5:$D$212, 2, 0), 0) -> 0 | S15: =(IFERROR(VLOOKUP(P15, 'Unit Database'!$C$5:$E$212, 3, 0), 0)*Q15) -> 0 | T15: =Q15*R15 -> 0
B16: PD11 - 230V 32A Bary Strømskap -> 6x16A | C16: 4 | G16: =IFERROR(VLOOKUP(E16, 'Unit Database'!$C$5:$D$212, 2, 0), 0) -> 0 | H16: =(IFERROR(VLOOKUP(E16, 'Unit Database'!$C$5:$E$212, 3, 0), 0)*F16) -> 0 | I16: =F16*G16 -> 0 | J16: =SUM(I16:I18) -> 0 | K16: =J16/3680 -> 0 | N16: 4 | R16: =IFERROR(VLOOKUP(P16, 'Unit Database'!$C$5:$D$212, 2, 0), 0) -> 0 | S16: =(IFERROR(VLOOKUP(P16, 'Unit Database'!$C$5:$E$212, 3, 0), 0)*Q16) -> 0 | T16: =Q16*R16 -> 0 | U16: =SUM(T16:T18) -> 0 | V16: =U16/3680 -> 0
G17: =IFERROR(VLOOKUP(E17, 'Unit Database'!$C$5:$D$212, 2, 0), 0) -> 0 | H17: =(IFERROR(VLOOKUP(E17, 'Unit Database'!$C$5:$E$212, 3, 0), 0)*F17) -> 0 | I17: =F17*G17 -> 0 | R17: =IFERROR(VLOOKUP(P17, 'Unit Database'!$C$5:$D$212, 2, 0), 0) -> 0 | S17: =(IFERROR(VLOOKUP(P17, 'Unit Database'!$C$5:$E$212, 3, 0), 0)*Q17) -> 0 | T17: =Q17*R17 -> 0
G18: =IFERROR(VLOOKUP(E18, 'Unit Database'!$C$5:$D$212, 2, 0), 0) -> 0 | H18: =(IFERROR(VLOOKUP(E18, 'Unit Database'!$C$5:$E$212, 3, 0), 0)*F18) -> 0 | I18: =F18*G18 -> 0 | R18: =IFERROR(VLOOKUP(P18, 'Unit Database'!$C$5:$D$212, 2, 0), 0) -> 0 | S18: =(IFERROR(VLOOKUP(P18, 'Unit Database'!$C$5:$E$212, 3, 0), 0)*Q18) -> 0 | T18: =Q18*R18 -> 0
B19: Capasity: | C19: 5 | E19: LA12X | F19: 1 | G19: =IFERROR(VLOOKUP(E19, 'Unit Database'!$C$5:$D$212, 2, 0), 0) -> 2600 | H19: =(IFERROR(VLOOKUP(E19, 'Unit Database'!$C$5:$E$212, 3, 0), 0)*F19) -> 0 | I19: =F19*G19 -> 2600 | J19: =SUM(I19:I21) -> 2600 | K19: =J19/3680 -> 0.70652174 | M19: Capasity: | N19: 5 | R19: =IFERROR(VLOOKUP(P19, 'Unit Database'!$C$5:$D$212, 2, 0), 0) -> 0 | S19: =(IFERROR(VLOOKUP(P19, 'Unit Database'!$C$5:$E$212, 3, 0), 0)*Q19) -> 0 | T19: =Q19*R19 -> 0 | U19: =SUM(T19:T21) -> 0 | V19: =U19/3680 -> 0
B20: =IFERROR(VLOOKUP(B16, DISTRO!$D$4:$N$53, 11, 0), 0) -> 12747.894 | G20: =IFERROR(VLOOKUP(E20, 'Unit Database'!$C$5:$D$212, 2, 0), 0) -> 0 | H20: =(IFERROR(VLOOKUP(E20, 'Unit Database'!$C$5:$E$212, 3, 0), 0)*F20) -> 0 | I20: =F20*G20 -> 0 | M20: =IFERROR(VLOOKUP(M16, DISTRO!$D$4:$N$53, 11, 0), 0) -> 0 | R20: =IFERROR(VLOOKUP(P20, 'Unit Database'!$C$5:$D$212, 2, 0), 0) -> 0 | S20: =(IFERROR(VLOOKUP(P20, 'Unit Database'!$C$5:$E$212, 3, 0), 0)*Q20) -> 0 | T20: =Q20*R20 -> 0
G21: =IFERROR(VLOOKUP(E21, 'Unit Database'!$C$5:$D$212, 2, 0), 0) -> 0 | H21: =(IFERROR(VLOOKUP(E21, 'Unit Database'!$C$5:$E$212, 3, 0), 0)*F21) -> 0 | I21: =F21*G21 -> 0 | R21: =IFERROR(VLOOKUP(P21, 'Unit Database'!$C$5:$D$212, 2, 0), 0) -> 0 | S21: =(IFERROR(VLOOKUP(P21, 'Unit Database'!$C$5:$E$212, 3, 0), 0)*Q21) -> 0 | T21: =Q21*R21 -> 0
B22: Soca Total | C22: 6 | E22: Generic Load | F22: 2 | G22: =IFERROR(VLOOKUP(E22, 'Unit Database'!$C$5:$D$212, 2, 0), 0) -> 1000 | H22: =(IFERROR(VLOOKUP(E22, 'Unit Database'!$C$5:$E$212, 3, 0), 0)*F22) -> 0 | I22: =F22*G22 -> 2000 | J22: =SUM(I22:I24) -> 2000 | K22: =J22/3680 -> 0.54347826 | M22: Soca Total | N22: 6 | R22: =IFERROR(VLOOKUP(P22, 'Unit Database'!$C$5:$D$212, 2, 0), 0) -> 0 | S22: =(IFERROR(VLOOKUP(P22, 'Unit Database'!$C$5:$E$212, 3, 0), 0)*Q22) -> 0 | T22: =Q22*R22 -> 0 | U22: =SUM(T22:T24) -> 0 | V22: =U22/3680 -> 0
B23: =SUM(J7:J24) -> 9372 | G23: =IFERROR(VLOOKUP(E23, 'Unit Database'!$C$5:$D$212, 2, 0), 0) -> 0 | H23: =(IFERROR(VLOOKUP(E23, 'Unit Database'!$C$5:$E$212, 3, 0), 0)*F23) -> 0 | I23: =F23*G23 -> 0 | M23: =SUM(U7:U24) -> 0 | R23: =IFERROR(VLOOKUP(P23, 'Unit Database'!$C$5:$D$212, 2, 0), 0) -> 0 | S23: =(IFERROR(VLOOKUP(P23, 'Unit Database'!$C$5:$E$212, 3, 0), 0)*Q23) -> 0 | T23: =Q23*R23 -> 0
G24: =IFERROR(VLOOKUP(E24, 'Unit Database'!$C$5:$D$212, 2, 0), 0) -> 0 | H24: =(IFERROR(VLOOKUP(E24, 'Unit Database'!$C$5:$E$212, 3, 0), 0)*F24) -> 0 | I24: =F24*G24 -> 0 | R24: =IFERROR(VLOOKUP(P24, 'Unit Database'!$C$5:$D$212, 2, 0), 0) -> 0 | S24: =(IFERROR(VLOOKUP(P24, 'Unit Database'!$C$5:$E$212, 3, 0), 0)*Q24) -> 0 | T24: =Q24*R24 -> 0
D26: Name | E26: What | F26: Amount | G26: Wattage | H26: Total Amp | I26: Line Load | J26: Circuit Load | K26: % Load | O26: Name | P26: What | Q26: Amount | R26: Wattage | S26: Total Amp | T26: Line Load | U26: Circuit Load | V26: % Load
B27: HOT 3 | C27: 1 | G27: =IFERROR(VLOOKUP(E27, 'Unit Database'!$C$5:$D$212, 2, 0), 0) -> 0 | H27: =(IFERROR(VLOOKUP(E27, 'Unit Database'!$C$5:$E$212, 3, 0), 0)*F27) -> 0 | I27: =F27*G27 -> 0 | J27: =SUM(I27:I29) -> 0 | K27: =J27/3680 -> 0 | M27: HOT 4 | N27: 1 | R27: =IFERROR(VLOOKUP(P27, 'Unit Database'!$C$5:$D$212, 2, 0), 0) -> 0 | S27: =(IFERROR(VLOOKUP(P27, 'Unit Database'!$C$5:$E$212, 3, 0), 0)*Q27) -> 0 | T27: =Q27*R27 -> 0 | U27: =SUM(T27:T29) -> 0 | V27: =U27/3680 -> 0
G28: =IFERROR(VLOOKUP(E28, 'Unit Database'!$C$5:$D$212, 2, 0), 0) -> 0 | H28: =(IFERROR(VLOOKUP(E28, 'Unit Database'!$C$5:$E$212, 3, 0), 0)*F28) -> 0 | I28: =F28*G28 -> 0 | R28: =IFERROR(VLOOKUP(P28, 'Unit Database'!$C$5:$D$212, 2, 0), 0) -> 0 | S28: =(IFERROR(VLOOKUP(P28, 'Unit Database'!$C$5:$E$212, 3, 0), 0)*Q28) -> 0 | T28: =Q28*R28 -> 0
G29: =IFERROR(VLOOKUP(E29, 'Unit Database'!$C$5:$D$212, 2, 0), 0) -> 0 | H29: =(IFERROR(VLOOKUP(E29, 'Unit Database'!$C$5:$E$212, 3, 0), 0)*F29) -> 0 | I29: =F29*G29 -> 0 | R29: =IFERROR(VLOOKUP(P29, 'Unit Database'!$C$5:$D$212, 2, 0), 0) -> 0 | S29: =(IFERROR(VLOOKUP(P29, 'Unit Database'!$C$5:$E$212, 3, 0), 0)*Q29) -> 0 | T29: =Q29*R29 -> 0
B30: Soca Name: | C30: 2 | G30: =IFERROR(VLOOKUP(E30, 'Unit Database'!$C$5:$D$212, 2, 0), 0) -> 0 | H30: =(IFERROR(VLOOKUP(E30, 'Unit Database'!$C$5:$E$212, 3, 0), 0)*F30) -> 0 | I30: =F30*G30 -> 0 | J30: =SUM(I30:I32) -> 0 | K30: =J30/3680 -> 0 | M30: Soca Name: | N30: 2 | R30: =IFERROR(VLOOKUP(P30, 'Unit Database'!$C$5:$D$212, 2, 0), 0) -> 0 | S30: =(IFERROR(VLOOKUP(P30, 'Unit Database'!$C$5:$E$212, 3, 0), 0)*Q30) -> 0 | T30: =Q30*R30 -> 0 | U30: =SUM(T30:T32) -> 0 | V30: =U30/3680 -> 0
G31: =IFERROR(VLOOKUP(E31, 'Unit Database'!$C$5:$D$212, 2, 0), 0) -> 0 | H31: =(IFERROR(VLOOKUP(E31, 'Unit Database'!$C$5:$E$212, 3, 0), 0)*F31) -> 0 | I31: =F31*G31 -> 0 | R31: =IFERROR(VLOOKUP(P31, 'Unit Database'!$C$5:$D$212, 2, 0), 0) -> 0 | S31: =(IFERROR(VLOOKUP(P31, 'Unit Database'!$C$5:$E$212, 3, 0), 0)*Q31) -> 0 | T31: =Q31*R31 -> 0
G32: =IFERROR(VLOOKUP(E32, 'Unit Database'!$C$5:$D$212, 2, 0), 0) -> 0 | H32: =(IFERROR(VLOOKUP(E32, 'Unit Database'!$C$5:$E$212, 3, 0), 0)*F32) -> 0 | I32: =F32*G32 -> 0 | R32: =IFERROR(VLOOKUP(P32, 'Unit Database'!$C$5:$D$212, 2, 0), 0) -> 0 | S32: =(IFERROR(VLOOKUP(P32, 'Unit Database'!$C$5:$E$212, 3, 0), 0)*Q32) -> 0 | T32: =Q32*R32 -> 0
C33: 3 | G33: =IFERROR(VLOOKUP(E33, 'Unit Database'!$C$5:$D$212, 2, 0), 0) -> 0 | H33: =(IFERROR(VLOOKUP(E33, 'Unit Database'!$C$5:$E$212, 3, 0), 0)*F33) -> 0 | I33: =F33*G33 -> 0 | J33: =SUM(I33:I35) -> 0 | K33: =J33/3680 -> 0 | N33: 3 | R33: =IFERROR(VLOOKUP(P33, 'Unit Database'!$C$5:$D$212, 2, 0), 0) -> 0 | S33: =(IFERROR(VLOOKUP(P33, 'Unit Database'!$C$5:$E$212, 3, 0), 0)*Q33) -> 0 | T33: =Q33*R33 -> 0 | U33: =SUM(T33:T35) -> 0 | V33: =U33/3680 -> 0
G34: =IFERROR(VLOOKUP(E34, 'Unit Database'!$C$5:$D$212, 2, 0), 0) -> 0 | H34: =(IFERROR(VLOOKUP(E34, 'Unit Database'!$C$5:$E$212, 3, 0), 0)*F34) -> 0 | I34: =F34*G34 -> 0 | R34: =IFERROR(VLOOKUP(P34, 'Unit Database'!$C$5:$D$212, 2, 0), 0) -> 0 | S34: =(IFERROR(VLOOKUP(P34, 'Unit Database'!$C$5:$E$212, 3, 0), 0)*Q34) -> 0 | T34: =Q34*R34 -> 0
B35: Input Power: | G35: =IFERROR(VLOOKUP(E35, 'Unit Database'!$C$5:$D$212, 2, 0), 0) -> 0 | H35: =(IFERROR(VLOOKUP(E35, 'Unit Database'!$C$5:$E$212, 3, 0), 0)*F35) -> 0 | I35: =F35*G35 -> 0 | M35: Input Power: | R35: =IFERROR(VLOOKUP(P35, 'Unit Database'!$C$5:$D$212, 2, 0), 0) -> 0 | S35: =(IFERROR(VLOOKUP(P35, 'Unit Database'!$C$5:$E$212, 3, 0), 0)*Q35) -> 0 | T35: =Q35*R35 -> 0
C36: 4 | G36: =IFERROR(VLOOKUP(E36, 'Unit Database'!$C$5:$D$212, 2, 0), 0) -> 0 | H36: =(IFERROR(VLOOKUP(E36, 'Unit Database'!$C$5:$E$212, 3, 0), 0)*F36) -> 0 | I36: =F36*G36 -> 0 | J36: =SUM(I36:I38) -> 0 | K36: =J36/3680 -> 0 | N36: 4 | R36: =IFERROR(VLOOKUP(P36, 'Unit Database'!$C$5:$D$212, 2, 0), 0) -> 0 | S36: =(IFERROR(VLOOKUP(P36, 'Unit Database'!$C$5:$E$212, 3, 0), 0)*Q36) -> 0 | T36: =Q36*R36 -> 0 | U36: =SUM(T36:T38) -> 0 | V36: =U36/3680 -> 0
G37: =IFERROR(VLOOKUP(E37, 'Unit Database'!$C$5:$D$212, 2, 0), 0) -> 0 | H37: =(IFERROR(VLOOKUP(E37, 'Unit Database'!$C$5:$E$212, 3, 0), 0)*F37) -> 0 | I37: =F37*G37 -> 0 | R37: =IFERROR(VLOOKUP(P37, 'Unit Database'!$C$5:$D$212, 2, 0), 0) -> 0 | S37: =(IFERROR(VLOOKUP(P37, 'Unit Database'!$C$5:$E$212, 3, 0), 0)*Q37) -> 0 | T37: =Q37*R37 -> 0
G38: =IFERROR(VLOOKUP(E38, 'Unit Database'!$C$5:$D$212, 2, 0), 0) -> 0 | H38: =(IFERROR(VLOOKUP(E38, 'Unit Database'!$C$5:$E$212, 3, 0), 0)*F38) -> 0 | I38: =F38*G38 -> 0 | R38: =IFERROR(VLOOKUP(P38, 'Unit Database'!$C$5:$D$212, 2, 0), 0) -> 0 | S38: =(IFERROR(VLOOKUP(P38, 'Unit Database'!$C$5:$E$212, 3, 0), 0)*Q38) -> 0 | T38: =Q38*R38 -> 0
B39: Capasity: | C39: 5 | G39: =IFERROR(VLOOKUP(E39, 'Unit Database'!$C$5:$D$212, 2, 0), 0) -> 0 | H39: =(IFERROR(VLOOKUP(E39, 'Unit Database'!$C$5:$E$212, 3, 0), 0)*F39) -> 0 | I39: =F39*G39 -> 0 | J39: =SUM(I39:I41) -> 0 | K39: =J39/3680 -> 0 | M39: Capasity: | N39: 5 | R39: =IFERROR(VLOOKUP(P39, 'Unit Database'!$C$5:$D$212, 2, 0), 0) -> 0 | S39: =(IFERROR(VLOOKUP(P39, 'Unit Database'!$C$5:$E$212, 3, 0), 0)*Q39) -> 0 | T39: =Q39*R39 -> 0 | U39: =SUM(T39:T41) -> 0 | V39: =U39/3680 -> 0
B40: =IFERROR(VLOOKUP(B36, DISTRO!$D$4:$N$53, 11, 0), 0) -> 0 | G40: =IFERROR(VLOOKUP(E40, 'Unit Database'!$C$5:$D$212, 2, 0), 0) -> 0 | H40: =(IFERROR(VLOOKUP(E40, 'Unit Database'!$C$5:$E$212, 3, 0), 0)*F40) -> 0 | I40: =F40*G40 -> 0 | M40: =IFERROR(VLOOKUP(M36, DISTRO!$D$4:$N$53, 11, 0), 0) -> 0 | R40: =IFERROR(VLOOKUP(P40, 'Unit Database'!$C$5:$D$212, 2, 0), 0) -> 0 | S40: =(IFERROR(VLOOKUP(P40, 'Unit Database'!$C$5:$E$212, 3, 0), 0)*Q40) -> 0 | T40: =Q40*R40 -> 0
G41: =IFERROR(VLOOKUP(E41, 'Unit Database'!$C$5:$D$212, 2, 0), 0) -> 0 | H41: =(IFERROR(VLOOKUP(E41, 'Unit Database'!$C$5:$E$212, 3, 0), 0)*F41) -> 0 | I41: =F41*G41 -> 0 | R41: =IFERROR(VLOOKUP(P41, 'Unit Database'!$C$5:$D$212, 2, 0), 0) -> 0 | S41: =(IFERROR(VLOOKUP(P41, 'Unit Database'!$C$5:$E$212, 3, 0), 0)*Q41) -> 0 | T41: =Q41*R41 -> 0
B42: Soca Total | C42: 6 | G42: =IFERROR(VLOOKUP(E42, 'Unit Database'!$C$5:$D$212, 2, 0), 0) -> 0 | H42: =(IFERROR(VLOOKUP(E42, 'Unit Database'!$C$5:$E$212, 3, 0), 0)*F42) -> 0 | I42: =F42*G42 -> 0 | J42: =SUM(I42:I44) -> 0 | K42: =J42/3680 -> 0 | M42: Soca Total | N42: 6 | R42: =IFERROR(VLOOKUP(P42, 'Unit Database'!$C$5:$D$212, 2, 0), 0) -> 0 | S42: =(IFERROR(VLOOKUP(P42, 'Unit Database'!$C$5:$E$212, 3, 0), 0)*Q42) -> 0 | T42: =Q42*R42 -> 0 | U42: =SUM(T42:T44) -> 0 | V42: =U42/3680 -> 0
B43: =SUM(J27:J44) -> 0 | G43: =IFERROR(VLOOKUP(E43, 'Unit Database'!$C$5:$D$212, 2, 0), 0) -> 0 | H43: =(IFERROR(VLOOKUP(E43, 'Unit Database'!$C$5:$E$212, 3, 0), 0)*F43) -> 0 | I43: =F43*G43 -> 0 | M43: =SUM(U27:U44) -> 0 | R43: =IFERROR(VLOOKUP(P43, 'Unit Database'!$C$5:$D$212, 2, 0), 0) -> 0 | S43: =(IFERROR(VLOOKUP(P43, 'Unit Database'!$C$5:$E$212, 3, 0), 0)*Q43) -> 0 | T43: =Q43*R43 -> 0
...

Sheet Soca Draw
B2: HOT Powerdraw
B3: Hot Nr | C3: Input Power | D3: L1 | E3: L2 | F3: L3 | G3: Total Power
B4: ='Power Calculation'!B7 -> HOT 1 | C4: ='Power Calculation'!B16 -> PD11 - 230V 32A Bary Strømskap -> 6x16A | D4: ='Power Calculation'!J7+'Power Calculation'!J16 -> 2272 | E4: ='Power Calculation'!J10+'Power Calculation'!J19 -> 4800 | F4: ='Power Calculation'!J13+'Power Calculation'!J22 -> 2300 | G4: =SUM(D4:F4) -> 9372
B5: ='Power Calculation'!M7 -> HOT 2 | C5: ='Power Calculation'!M16 -> 0 | D5: ='Power Calculation'!U7+'Power Calculation'!U16 -> 0 | E5: ='Power Calculation'!U10+'Power Calculation'!U19 -> 0 | F5: ='Power Calculation'!U13+'Power Calculation'!U22 -> 0 | G5: =SUM(D5:F5) -> 0
B6: ='Power Calculation'!B27 -> HOT 3 | C6: ='Power Calculation'!B36 -> 0 | D6: ='Power Calculation'!J27+'Power Calculation'!J36 -> 0 | E6: ='Power Calculation'!J30+'Power Calculation'!J39 -> 0 | F6: ='Power Calculation'!J33+'Power Calculation'!J42 -> 0 | G6: =SUM(D6:F6) -> 0
B7: ='Power Calculation'!M27 -> HOT 4 | C7: ='Power Calculation'!M36 -> 0 | D7: ='Power Calculation'!U27+'Power Calculation'!U36 -> 0 | E7: ='Power Calculation'!U30+'Power Calculation'!U39 -> 0 | F7: ='Power Calculation'!U33+'Power Calculation'!U42 -> 0 | G7: =SUM(D7:F7) -> 0
B8: ='Power Calculation'!B52 -> HOT 5 | C8: ='Power Calculation'!B61 -> 0 | D8: ='Power Calculation'!J52+'Power Calculation'!J61 -> 0 | E8: ='Power Calculation'!J55+'Power Calculation'!J64 -> 0 | F8: ='Power Calculation'!J58+'Power Calculation'!J67 -> 0 | G8: =SUM(D8:F8) -> 0
B9: ='Power Calculation'!M52 -> HOT 6 | C9: ='Power Calculation'!M61 -> 0 | D9: ='Power Calculation'!U52+'Power Calculation'!U61 -> 0 | E9: ='Power Calculation'!U55+'Power Calculation'!U64 -> 0 | F9: ='Power Calculation'!U58+'Power Calculation'!U67 -> 0 | G9: =SUM(D9:F9) -> 0
B10: ='Power Calculation'!B72 -> HOT 7 | C10: ='Power Calculation'!B81 -> 0 | D10: ='Power Calculation'!J72+'Power Calculation'!J81 -> 0 | E10: ='Power Calculation'!J75+'Power Calculation'!J84 -> 0 | F10: ='Power Calculation'!J78+'Power Calculation'!J87 -> 0 | G10: =SUM(D10:F10) -> 0
B11: ='Power Calculation'!M72 -> HOT 8 | C11: ='Power Calculation'!M81 -> 0 | D11: ='Power Calculation'!U72+'Power Calculation'!U81 -> 0 | E11: ='Power Calculation'!U75+'Power Calculation'!U84 -> 0 | F11: ='Power Calculation'!U78+'Power Calculation'!U87 -> 0 | G11: =SUM(D11:F11) -> 0
B12: ='Power Calculation'!B97 -> HOT 9 | C12: ='Power Calculation'!B106 -> 0 | D12: ='Power Calculation'!J97+'Power Calculation'!J106 -> 0 | E12: ='Power Calculation'!J100+'Power Calculation'!J109 -> 0 | F12: ='Power Calculation'!J112+'Power Calculation'!J103 -> 0 | G12: =SUM(D12:F12) -> 0
B13: ='Power Calculation'!M97 -> HOT 10 | C13: ='Power Calculation'!M106 -> 0 | D13: ='Power Calculation'!U97+'Power Calculation'!U106 -> 0 | E13: ='Power Calculation'!U100+'Power Calculation'!U109 -> 0 | F13: ='Power Calculation'!U103+'Power Calculation'!U112 -> 0 | G13: =SUM(D13:F13) -> 0
B14: ='Power Calculation'!B117 -> HOT 11 | C14: ='Power Calculation'!B126 -> 0 | D14: ='Power Calculation'!J117+'Power Calculation'!J126 -> 0 | E14: ='Power Calculation'!J120+'Power Calculation'!J129 -> 0 | F14: ='Power Calculation'!J123+'Power Calculation'!J132 -> 0 | G14: =SUM(D14:F14) -> 0
B15: ='Power Calculation'!M117 -> HOT 12 | C15: ='Power Calculation'!M126 -> 0 | D15: ='Power Calculation'!U117+'Power Calculation'!U126 -> 0 | E15: ='Power Calculation'!U120+'Power Calculation'!U129 -> 0 | F15: ='Power Calculation'!U123+'Power Calculation'!U132 -> 0 | G15: =SUM(D15:F15) -> 0
B16: ='Power Calculation'!B142 -> HOT 13 | C16: ='Power Calculation'!B151 -> 0 | D16: ='Power Calculation'!J142+'Power Calculation'!J151 -> 0 | E16: ='Power Calculation'!J145+'Power Calculation'!J154 -> 0 | F16: ='Power Calculation'!J148+'Power Calculation'!J157 -> 0 | G16: =SUM(D16:F16) -> 0
B17: ='Power Calculation'!M142 -> HOT 14 | C17: ='Power Calculation'!M151 -> 0 | D17: ='Power Calculation'!U142+'Power Calculation'!U151 -> 0 | E17: ='Power Calculation'!U145+'Power Calculation'!U154 -> 0 | F17: ='Power Calculation'!U148+'Power Calculation'!U157 -> 0 | G17: =SUM(D17:F17) -> 0
B18: ='Power Calculation'!B162 -> HOT 15 | C18: ='Power Calculation'!B171 -> 0 | D18: ='Power Calculation'!J162+'Power Calculation'!J171 -> 0 | E18: ='Power Calculation'!J165+'Power Calculation'!J174 -> 0 | F18: ='Power Calculation'!J168+'Power Calculation'!J177 -> 0 | G18: =SUM(D18:F18) -> 0
B19: ='Power Calculation'!M162 -> HOT 16 | C19: ='Power Calculation'!M171 -> 0 | D19: ='Power Calculation'!U162+'Power Calculation'!U171 -> 0 | E19: ='Power Calculation'!U165+'Power Calculation'!U174 -> 0 | F19: ='Power Calculation'!U168+'Power Calculation'!U177 -> 0 | G19: =SUM(D19:F19) -> 0
B20: ='Power Calculation'!B187 -> HOT 17 | C20: ='Power Calculation'!B196 -> 0 | D20: ='Power Calculation'!J187+'Power Calculation'!J196 -> 0 | E20: ='Power Calculation'!J190+'Power Calculation'!J199 -> 0 | F20: ='Power Calculation'!J193+'Power Calculation'!J202 -> 0 | G20: =SUM(D20:F20) -> 0
B21: ='Power Calculation'!M187 -> HOT 18 | C21: ='Power Calculation'!M196 -> 0 | D21: ='Power Calculation'!U187+'Power Calculation'!U196 -> 0 | E21: ='Power Calculation'!U190+'Power Calculation'!U199 -> 0 | F21: ='Power Calculation'!U193+'Power Calculation'!U202 -> 0 | G21: =SUM(D21:F21) -> 0
B22: ='Power Calculation'!B207 -> HOT 19 | C22: ='Power Calculation'!B216 -> 0 | D22: ='Power Calculation'!J207+'Power Calculation'!J216 -> 0 | E22: ='Power Calculation'!J210+'Power Calculation'!J219 -> 0 | F22: ='Power Calculation'!J213+'Power Calculation'!J222 -> 0 | G22: =SUM(D22:F22) -> 0
B23: ='Power Calculation'!M207 -> HOT 20 | C23: ='Power Calculation'!M216 -> 0 | D23: ='Power Calculation'!U207+'Power Calculation'!U216 -> 0 | E23: ='Power Calculation'!U210+'Power Calculation'!U219 -> 0 | F23: ='Power Calculation'!U213+'Power Calculation'!U222 -> 0 | G23: =SUM(D23:F23) -> 0
B24: ='Power Calculation'!B232 -> HOT 21 | C24: ='Power Calculation'!B241 -> 0 | D24: ='Power Calculation'!J232+'Power Calculation'!J241 -> 0 | E24: ='Power Calculation'!J235+'Power Calculation'!J244 -> 0 | F24: ='Power Calculation'!J238+'Power Calculation'!J247 -> 0 | G24: =SUM(D24:F24) -> 0
B25: ='Power Calculation'!M232 -> HOT 22 | C25: ='Power Calculation'!M241 -> 0 | D25: ='Power Calculation'!U232+'Power Calculation'!U241 -> 0 | E25: ='Power Calculation'!U235+'Power Calculation'!U244 -> 0 | F25: ='Power Calculation'!U238+'Power Calculation'!U247 -> 0 | G25: =SUM(D25:F25) -> 0
B26: ='Power Calculation'!B252 -> HOT 23 | C26: ='Power Calculation'!B261 -> 0 | D26: ='Power Calculation'!J252+'Power Calculation'!J261 -> 0 | E26: ='Power Calculation'!J255+'Power Calculation'!J264 -> 0 | F26: ='Power Calculation'!J258+'Power Calculation'!J267 -> 0 | G26: =SUM(D26:F26) -> 0
B27: ='Power Calculation'!M252 -> HOT 24 | C27: ='Power Calculation'!M261 -> 0 | D27: ='Power Calculation'!U252+'Power Calculation'!U261 -> 0 | E27: ='Power Calculation'!U255+'Power Calculation'!U264 -> 0 | F27: ='Power Calculation'!U258+'Power Calculation'!U267 -> 0 | G27: =SUM(D27:F27) -> 0
B28: ='Power Calculation'!B277 -> HOT 25 | C28: ='Power Calculation'!B286 -> 0 | D28: ='Power Calculation'!J277+'Power Calculation'!J286 -> 0 | E28: ='Power Calculation'!J280+'Power Calculation'!J289 -> 0 | F28: ='Power Calculation'!J283+'Power Calculation'!J292 -> 0 | G28: =SUM(D28:F28) -> 0
B29: ='Power Calculation'!M277 -> HOT 26 | C29: ='Power Calculation'!M286 -> 0 | D29: ='Power Calculation'!U277+'Power Calculation'!U286 -> 0 | E29: ='Power Calculation'!U280+'Power Calculation'!U289 -> 0 | F29: ='Power Calculation'!U283+'Power Calculation'!U292 -> 0 | G29: =SUM(D29:F29) -> 0
B30: ='Power Calculation'!B297 -> HOT 27 | C30: ='Power Calculation'!B306 -> 0 | D30: ='Power Calculation'!J297+'Power Calculation'!J306 -> 0 | E30: ='Power Calculation'!J300+'Power Calculation'!J309 -> 0 | F30: ='Power Calculation'!J303+'Power Calculation'!J312 -> 0 | G30: =SUM(D30:F30) -> 0
B31: ='Power Calculation'!M297 -> HOT 28 | C31: ='Power Calculation'!M306 -> 0 | D31: ='Power Calculation'!U297+'Power Calculation'!U306 -> 0 | E31: ='Power Calculation'!U300+'Power Calculation'!U309 -> 0 | F31: ='Power Calculation'!U303+'Power Calculation'!U312 -> 0 | G31: =SUM(D31:F31) -> 0

Sheet DISTRO
H2: Farge Forklaring: | I2: >100% | J2: >80%
B3: Type | C3: Distro ID | D3: String Splice | E3: Name / Note | F3: Item | G3: Distro Input | H3: Distro Port | J3: L2 | K3: L3 | L3: Power Draw | M3: Power Draw % | N3: Capasity | O3: 1ph Cap
B4: Source Power | C4: PD01 | D4: =CONCATENATE(C4," - ",F4) -> PD01 - 230V 32 Amp | F4: 230V 32 Amp | G4: N/A | I4: =SUMIF($G$14:$G$53,"="&D4,$I$14:$I$53) + SUMIF('Soca Draw'!$C$4:$C$31,"="&$D4,'Soca Draw'!$D$4:$D$31) -> 2272 | J4: =SUMIF($G$14:$G$53,"="&D4,$J$14:$J$53) + SUMIF('Soca Draw'!$C$4:$C$31,"="&$D4,'Soca Draw'!$E$4:$E$31) -> 4800 | K4: =SUMIF($G$14:$G$53,"="&D4,$K$14:$K$53) + SUMIF('Soca Draw'!$C$4:$C$31,"="&$D4,'Soca Draw'!$F$4:$F$31) -> 2300 | L4: =SUM(I4:K4) -> 9372 | M4: =IFERROR((L4/N4), 0) -> 0.73518026 | N4: =IFERROR(VLOOKUP(F4, 'Source Power Database'!$C$5:$D$200, 2, 0), 0) -> 12747.894 | O4: =N4/3 -> 4249.298
C5: PD02 | D5: =CONCATENATE(C5," - ",F5) -> PD02 - | G5: N/A | I5: =SUMIF($G$14:$G$53,"="&D5,$I$14:$I$53) + SUMIF('Soca Draw'!$C$4:$C$31,"="&$D5,'Soca Draw'!$D$4:$D$31) -> 0 | J5: =SUMIF($G$14:$G$53,"="&D5,$J$14:$J$53) + SUMIF('Soca Draw'!$C$4:$C$31,"="&$D5,'Soca Draw'!$E$4:$E$31) -> 0 | K5: =SUMIF($G$14:$G$53,"="&D5,$K$14:$K$53) + SUMIF('Soca Draw'!$C$4:$C$31,"="&$D5,'Soca Draw'!$F$4:$F$31) -> 0 | L5: =SUM(I5:K5) -> 0 | M5: =IFERROR((L5/N5), 0) -> 0 | N5: =IFERROR(VLOOKUP(F5, 'Source Power Database'!$C$5:$D$200, 2, 0), 0) -> 0 | O5: =N5/3 -> 0
C6: PD03 | D6: =CONCATENATE(C6," - ",F6) -> PD03 - | G6: N/A | I6: =SUMIF($G$14:$G$53,"="&D6,$I$14:$I$53) + SUMIF('Soca Draw'!$C$4:$C$31,"="&$D6,'Soca Draw'!$D$4:$D$31) -> 0 | J6: =SUMIF($G$14:$G$53,"="&D6,$J$14:$J$53) + SUMIF('Soca Draw'!$C$4:$C$31,"="&$D6,'Soca Draw'!$E$4:$E$31) -> 0 | K6: =SUMIF($G$14:$G$53,"="&D6,$K$14:$K$53) + SUMIF('Soca Draw'!$C$4:$C$31,"="&$D6,'Soca Draw'!$F$4:$F$31) -> 0 | L6: =SUM(I6:K6) -> 0 | M6: =IFERROR((L6/N6), 0) -> 0 | N6: =IFERROR(VLOOKUP(F6, 'Source Power Database'!$C$5:$D$200, 2, 0), 0) -> 0 | O6: =N6/3 -> 0
C7: PD04 | D7: =CONCATENATE(C7," - ",F7) -> PD04 - | G7: N/A | I7: =SUMIF($G$14:$G$53,"="&D7,$I$14:$I$53) + SUMIF('Soca Draw'!$C$4:$C$31,"="&$D7,'Soca Draw'!$D$4:$D$31) -> 0 | J7: =SUMIF($G$14:$G$53,"="&D7,$J$14:$J$53) + SUMIF('Soca Draw'!$C$4:$C$31,"="&$D7,'Soca Draw'!$E$4:$E$31) -> 0 | K7: =SUMIF($G$14:$G$53,"="&D7,$K$14:$K$53) + SUMIF('Soca Draw'!$C$4:$C$31,"="&$D7,'Soca Draw'!$F$4:$F$31) -> 0 | L7: =SUM(I7:K7) -> 0 | M7: =IFERROR((L7/N7), 0) -> 0 | N7: =IFERROR(VLOOKUP(F7, 'Source Power Database'!$C$5:$D$200, 2, 0), 0) -> 0 | O7: =N7/3 -> 0
C8: PD05 | D8: =CONCATENATE(C8," - ",F8) -> PD05 - | G8: N/A | I8: =SUMIF($G$14:$G$53,"="&D8,$I$14:$I$53) + SUMIF('Soca Draw'!$C$4:$C$31,"="&$D8,'Soca Draw'!$D$4:$D$31) -> 0 | J8: =SUMIF($G$14:$G$53,"="&D8,$J$14:$J$53) + SUMIF('Soca Draw'!$C$4:$C$31,"="&$D8,'Soca Draw'!$E$4:$E$31) -> 0 | K8: =SUMIF($G$14:$G$53,"="&D8,$K$14:$K$53) + SUMIF('Soca Draw'!$C$4:$C$31,"="&$D8,'Soca Draw'!$F$4:$F$31) -> 0 | L8: =SUM(I8:K8) -> 0 | M8: =IFERROR((L8/N8), 0) -> 0 | N8: =IFERROR(VLOOKUP(F8, 'Source Power Database'!$C$5:$D$200, 2, 0), 0) -> 0 | O8: =N8/3 -> 0
C9: PD06 | D9: =CONCATENATE(C9," - ",F9) -> PD06 - | G9: N/A | I9: =SUMIF($G$14:$G$53,"="&D9,$I$14:$I$53) + SUMIF('Soca Draw'!$C$4:$C$31,"="&$D9,'Soca Draw'!$D$4:$D$31) -> 0 | J9: =SUMIF($G$14:$G$53,"="&D9,$J$14:$J$53) + SUMIF('Soca Draw'!$C$4:$C$31,"="&$D9,'Soca Draw'!$E$4:$E$31) -> 0 | K9: =SUMIF($G$14:$G$53,"="&D9,$K$14:$K$53) + SUMIF('Soca Draw'!$C$4:$C$31,"="&$D9,'Soca Draw'!$F$4:$F$31) -> 0 | L9: =SUM(I9:K9) -> 0 | M9: =IFERROR((L9/N9), 0) -> 0 | N9: =IFERROR(VLOOKUP(F9, 'Source Power Database'!$C$5:$D$200, 2, 0), 0) -> 0 | O9: =N9/3 -> 0
C10: PD07 | D10: =CONCATENATE(C10," - ",F10) -> PD07 - | G10: N/A | I10: =SUMIF($G$14:$G$53,"="&D10,$I$14:$I$53) + SUMIF('Soca Draw'!$C$4:$C$31,"="&$D10,'Soca Draw'!$D$4:$D$31) -> 0 | J10: =SUMIF($G$14:$G$53,"="&D10,$J$14:$J$53) + SUMIF('Soca Draw'!$C$4:$C$31,"="&$D10,'Soca Draw'!$E$4:$E$31) -> 0 | K10: =SUMIF($G$14:$G$53,"="&D10,$K$14:$K$53) + SUMIF('Soca Draw'!$C$4:$C$31,"="&$D10,'Soca Draw'!$F$4:$F$31) -> 0 | L10: =SUM(I10:K10) -> 0 | M10: =IFERROR((L10/N10), 0) -> 0 | N10: =IFERROR(VLOOKUP(F10, 'Source Power Database'!$C$5:$D$200, 2, 0), 0) -> 0 | O10: =N10/3 -> 0
C11: PD08 | D11: =CONCATENATE(C11," - ",F11) -> PD08 - | G11: N/A | I11: =SUMIF($G$14:$G$53,"="&D11,$I$14:$I$53) + SUMIF('Soca Draw'!$C$4:$C$31,"="&$D11,'Soca Draw'!$D$4:$D$31) -> 0 | J11: =SUMIF($G$14:$G$53,"="&D11,$J$14:$J$53) + SUMIF('Soca Draw'!$C$4:$C$31,"="&$D11,'Soca Draw'!$E$4:$E$31) -> 0 | K11: =SUMIF($G$14:$G$53,"="&D11,$K$14:$K$53) + SUMIF('Soca Draw'!$C$4:$C$31,"="&$D11,'Soca Draw'!$F$4:$F$31) -> 0 | L11: =SUM(I11:K11) -> 0 | M11: =IFERROR((L11/N11), 0) -> 0 | N11: =IFERROR(VLOOKUP(F11, 'Source Power Database'!$C$5:$D$200, 2, 0), 0) -> 0 | O11: =N11/3 -> 0
C12: PD09 | D12: =CONCATENATE(C12," - ",F12) -> PD09 - | G12: N/A | I12: =SUMIF($G$14:$G$53,"="&D12,$I$14:$I$53) + SUMIF('Soca Draw'!$C$4:$C$31,"="&$D12,'Soca Draw'!$D$4:$D$31) -> 0 | J12: =SUMIF($G$14:$G$53,"="&D12,$J$14:$J$53) + SUMIF('Soca Draw'!$C$4:$C$31,"="&$D12,'Soca Draw'!$E$4:$E$31) -> 0 | K12: =SUMIF($G$14:$G$53,"="&D12,$K$14:$K$53) + SUMIF('Soca Draw'!$C$4:$C$31,"="&$D12,'Soca Draw'!$F$4:$F$31) -> 0 | L12: =SUM(I12:K12) -> 0 | M12: =IFERROR((L12/N12), 0) -> 0 | N12: =IFERROR(VLOOKUP(F12, 'Source Power Database'!$C$5:$D$200, 2, 0), 0) -> 0 | O12: =N12/3 -> 0
C13: PD10 | D13: =CONCATENATE(C13," - ",F13) -> PD10 - | G13: N/A | I13: =SUMIF($G$14:$G$53,"="&D13,$I$14:$I$53) + SUMIF('Soca Draw'!$C$4:$C$31,"="&$D13,'Soca Draw'!$D$4:$D$31) -> 0 | J13: =SUMIF($G$14:$G$53,"="&D13,$J$14:$J$53) + SUMIF('Soca Draw'!$C$4:$C$31,"="&$D13,'Soca Draw'!$E$4:$E$31) -> 0 | K13: =SUMIF($G$14:$G$53,"="&D13,$K$14:$K$53) + SUMIF('Soca Draw'!$C$4:$C$31,"="&$D13,'Soca Draw'!$F$4:$F$31) -> 0 | L13: =SUM(I13:K13) -> 0 | M13: =IFERROR((L13/N13), 0) -> 0 | N13: =IFERROR(VLOOKUP(F13, 'Source Power Database'!$C$5:$D$200, 2, 0), 0) -> 0 | O13: =N13/3 -> 0
B14: Distro 1 | C14: PD11 | D14: =CONCATENATE(C14," - ",F14) -> PD11 - 230V 32A Bary Strømskap -> 6x16A | F14: 230V 32A Bary Strømskap -> 6x16A | G14: PD01 - 230V 32 Amp | I14: =SUMIF($G$14:$G$53,"="&D14,$I$14:$I$53) + SUMIF('Soca Draw'!$C$4:$C$31,"="&$D14,'Soca Draw'!$D$4:$D$31) -> 2272 | J14: =SUMIF($G$14:$G$53,"="&D14,$J$14:$J$53) + SUMIF('Soca Draw'!$C$4:$C$31,"="&$D14,'Soca Draw'!$E$4:$E$31) -> 4800 | K14: =SUMIF($G$14:$G$53,"="&D14,$K$14:$K$53) + SUMIF('Soca Draw'!$C$4:$C$31,"="&$D14,'Soca Draw'!$F$4:$F$31) -> 2300 | L14: =SUM(I14:K14) -> 9372 | M14: =IFERROR((L14/N14), 0) -> 0.73518026 | N14: =IFERROR(VLOOKUP(F14, 'Distro Database'!$C$5:$D$200, 2, 0), IFERROR(VLOOKUP(G14, D4:N13, 5, 0), 0)) -> 12747.894 | O14: =N14/3 -> 4249.298
C15: PD12 | D15: =CONCATENATE(C15," - ",F15) -> PD12 - | I15: =SUMIF($G$14:$G$53,"="&D15,$I$14:$I$53) + SUMIF('Soca Draw'!$C$4:$C$31,"="&$D15,'Soca Draw'!$D$4:$D$31) -> 0 | J15: =SUMIF($G$14:$G$53,"="&D15,$J$14:$J$53) + SUMIF('Soca Draw'!$C$4:$C$31,"="&$D15,'Soca Draw'!$E$4:$E$31) -> 0 | K15: =SUMIF($G$14:$G$53,"="&D15,$K$14:$K$53) + SUMIF('Soca Draw'!$C$4:$C$31,"="&$D15,'Soca Draw'!$F$4:$F$31) -> 0 | L15: =SUM(I15:K15) -> 0 | M15: =IFERROR((L15/N15), 0) -> 0 | N15: =IFERROR(VLOOKUP(F15, 'Distro Database'!$C$5:$D$200, 2, 0), IFERROR(VLOOKUP(G15, D5:N14, 5, 0), 0)) -> 0 | O15: =N15/3 -> 0
C16: PD13 | D16: =CONCATENATE(C16," - ",F16) -> PD13 - | I16: =SUMIF($G$14:$G$53,"="&D16,$I$14:$I$53) + SUMIF('Soca Draw'!$C$4:$C$31,"="&$D16,'Soca Draw'!$D$4:$D$31) -> 0 | J16: =SUMIF($G$14:$G$53,"="&D16,$J$14:$J$53) + SUMIF('Soca Draw'!$C$4:$C$31,"="&$D16,'Soca Draw'!$E$4:$E$31) -> 0 | K16: =SUMIF($G$14:$G$53,"="&D16,$K$14:$K$53) + SUMIF('Soca Draw'!$C$4:$C$31,"="&$D16,'Soca Draw'!$F$4:$F$31) -> 0 | L16: =SUM(I16:K16) -> 0 | M16: =IFERROR((L16/N16), 0) -> 0 | N16: =IFERROR(VLOOKUP(F16, 'Distro Database'!$C$5:$D$200, 2, 0), IFERROR(VLOOKUP(G16, D6:N15, 5, 0), 0)) -> 0 | O16: =N16/3 -> 0
C17: PD14 | D17: =CONCATENATE(C17," - ",F17) -> PD14 - | I17: =SUMIF($G$14:$G$53,"="&D17,$I$14:$I$53) + SUMIF('Soca Draw'!$C$4:$C$31,"="&$D17,'Soca Draw'!$D$4:$D$31) -> 0 | J17: =SUMIF($G$14:$G$53,"="&D17,$J$14:$J$53) + SUMIF('Soca Draw'!$C$4:$C$31,"="&$D17,'Soca Draw'!$E$4:$E$31) -> 0 | K17: =SUMIF($G$14:$G$53,"="&D17,$K$14:$K$53) + SUMIF('Soca Draw'!$C$4:$C$31,"="&$D17,'Soca Draw'!$F$4:$F$31) -> 0 | L17: =SUM(I17:K17) -> 0 | M17: =IFERROR((L17/N17), 0) -> 0 | N17: =IFERROR(VLOOKUP(F17, 'Distro Database'!$C$5:$D$200, 2, 0), IFERROR(VLOOKUP(G17, D7:N16, 5, 0), 0)) -> 0 | O17: =N17/3 -> 0
C18: PD15 | D18: =CONCATENATE(C18," - ",F18) -> PD15 - | I18: =SUMIF($G$14:$G$53,"="&D18,$I$14:$I$53) + SUMIF('Soca Draw'!$C$4:$C$31,"="&$D18,'Soca Draw'!$D$4:$D$31) -> 0 | J18: =SUMIF($G$14:$G$53,"="&D18,$J$14:$J$53) + SUMIF('Soca Draw'!$C$4:$C$31,"="&$D18,'Soca Draw'!$E$4:$E$31) -> 0 | K18: =SUMIF($G$14:$G$53,"="&D18,$K$14:$K$53) + SUMIF('Soca Draw'!$C$4:$C$31,"="&$D18,'Soca Draw'!$F$4:$F$31) -> 0 | L18: =SUM(I18:K18) -> 0 | M18: =IFERROR((L18/N18), 0) -> 0 | N18: =IFERROR(VLOOKUP(F18, 'Distro Database'!$C$5:$D$200, 2, 0), IFERROR(VLOOKUP(G18, D8:N17, 5, 0), 0)) -> 0 | O18: =N18/3 -> 0
C19: PD16 | D19: =CONCATENATE(C19," - ",F19) -> PD16 - | I19: =SUMIF($G$14:$G$53,"="&D19,$I$14:$I$53) + SUMIF('Soca Draw'!$C$4:$C$31,"="&$D19,'Soca Draw'!$D$4:$D$31) -> 0 | J19: =SUMIF($G$14:$G$53,"="&D19,$J$14:$J$53) + SUMIF('Soca Draw'!$C$4:$C$31,"="&$D19,'Soca Draw'!$E$4:$E$31) -> 0 | K19: =SUMIF($G$14:$G$53,"="&D19,$K$14:$K$53) + SUMIF('Soca Draw'!$C$4:$C$31,"="&$D19,'Soca Draw'!$F$4:$F$31) -> 0 | L19: =SUM(I19:K19) -> 0 | M19: =IFERROR((L19/N19), 0) -> 0 | N19: =IFERROR(VLOOKUP(F19, 'Distro Database'!$C$5:$D$200, 2, 0), IFERROR(VLOOKUP(G19, D9:N18, 5, 0), 0)) -> 0 | O19: =N19/3 -> 0
C20: PD17 | D20: =CONCATENATE(C20," - ",F20) -> PD17 - | I20: =SUMIF($G$14:$G$53,"="&D20,$I$14:$I$53) + SUMIF('Soca Draw'!$C$4:$C$31,"="&$D20,'Soca Draw'!$D$4:$D$31) -> 0 | J20: =SUMIF($G$14:$G$53,"="&D20,$J$14:$J$53) + SUMIF('Soca Draw'!$C$4:$C$31,"="&$D20,'Soca Draw'!$E$4:$E$31) -> 0 | K20: =SUMIF($G$14:$G$53,"="&D20,$K$14:$K$53) + SUMIF('Soca Draw'!$C$4:$C$31,"="&$D20,'Soca Draw'!$F$4:$F$31) -> 0 | L20: =SUM(I20:K20) -> 0 | M20: =IFERROR((L20/N20), 0) -> 0 | N20: =IFERROR(VLOOKUP(F20, 'Distro Database'!$C$5:$D$200, 2, 0), IFERROR(VLOOKUP(G20, D10:N19, 5, 0), 0)) -> 0 | O20: =N20/3 -> 0
C21: PD18 | D21: =CONCATENATE(C21," - ",F21) -> PD18 - | I21: =SUMIF($G$14:$G$53,"="&D21,$I$14:$I$53) + SUMIF('Soca Draw'!$C$4:$C$31,"="&$D21,'Soca Draw'!$D$4:$D$31) -> 0 | J21: =SUMIF($G$14:$G$53,"="&D21,$J$14:$J$53) + SUMIF('Soca Draw'!$C$4:$C$31,"="&$D21,'Soca Draw'!$E$4:$E$31) -> 0 | K21: =SUMIF($G$14:$G$53,"="&D21,$K$14:$K$53) + SUMIF('Soca Draw'!$C$4:$C$31,"="&$D21,'Soca Draw'!$F$4:$F$31) -> 0 | L21: =SUM(I21:K21) -> 0 | M21: =IFERROR((L21/N21), 0) -> 0 | N21: =IFERROR(VLOOKUP(F21, 'Distro Database'!$C$5:$D$200, 2, 0), IFERROR(VLOOKUP(G21, D11:N20, 5, 0), 0)) -> 0 | O21: =N21/3 -> 0
C22: PD19 | D22: =CONCATENATE(C22," - ",F22) -> PD19 - | I22: =SUMIF($G$14:$G$53,"="&D22,$I$14:$I$53) + SUMIF('Soca Draw'!$C$4:$C$31,"="&$D22,'Soca Draw'!$D$4:$D$31) -> 0 | J22: =SUMIF($G$14:$G$53,"="&D22,$J$14:$J$53) + SUMIF('Soca Draw'!$C$4:$C$31,"="&$D22,'Soca Draw'!$E$4:$E$31) -> 0 | K22: =SUMIF($G$14:$G$53,"="&D22,$K$14:$K$53) + SUMIF('Soca Draw'!$C$4:$C$31,"="&$D22,'Soca Draw'!$F$4:$F$31) -> 0 | L22: =SUM(I22:K22) -> 0 | M22: =IFERROR((L22/N22), 0) -> 0 | N22: =IFERROR(VLOOKUP(F22, 'Distro Database'!$C$5:$D$200, 2, 0), IFERROR(VLOOKUP(G22, D12:N21, 5, 0), 0)) -> 0 | O22: =N22/3 -> 0
C23: PD20 | D23: =CONCATENATE(C23," - ",F23) -> PD20 - | I23: =SUMIF($G$14:$G$53,"="&D23,$I$14:$I$53) + SUMIF('Soca Draw'!$C$4:$C$31,"="&$D23,'Soca Draw'!$D$4:$D$31) -> 0 | J23: =SUMIF($G$14:$G$53,"="&D23,$J$14:$J$53) + SUMIF('Soca Draw'!$C$4:$C$31,"="&$D23,'Soca Draw'!$E$4:$E$31) -> 0 | K23: =SUMIF($G$14:$G$53,"="&D23,$K$14:$K$53) + SUMIF('Soca Draw'!$C$4:$C$31,"="&$D23,'Soca Draw'!$F$4:$F$31) -> 0 | L23: =SUM(I23:K23) -> 0 | M23: =IFERROR((L23/N23), 0) -> 0 | N23: =IFERROR(VLOOKUP(F23, 'Distro Database'!$C$5:$D$200, 2, 0), IFERROR(VLOOKUP(G23, D13:N22, 5, 0), 0)) -> 0 | O23: =N23/3 -> 0
B24: Distro 2 | C24: PD21 | D24: =CONCATENATE(C24," - ",F24) -> PD21 - | I24: =SUMIF($G$14:$G$53,"="&D24,$I$14:$I$53) + SUMIF('Soca Draw'!$C$4:$C$31,"="&$D24,'Soca Draw'!$D$4:$D$31) -> 0 | J24: =SUMIF($G$14:$G$53,"="&D24,$J$14:$J$53) + SUMIF('Soca Draw'!$C$4:$C$31,"="&$D24,'Soca Draw'!$E$4:$E$31) -> 0 | K24: =SUMIF($G$14:$G$53,"="&D24,$K$14:$K$53) + SUMIF('Soca Draw'!$C$4:$C$31,"="&$D24,'Soca Draw'!$F$4:$F$31) -> 0 | L24: =SUM(I24:K24) -> 0 | M24: =IFERROR((L24/N24), 0) -> 0 | N24: =IFERROR(VLOOKUP(F24, 'Distro Database'!$C$5:$D$200, 2, 0), IFERROR(VLOOKUP(G24, D14:N23, 5, 0), 0)) -> 0 | O24: =N24/3 -> 0
C25: PD22 | D25: =CONCATENATE(C25," - ",F25) -> PD22 - | I25: =SUMIF($G$14:$G$53,"="&D25,$I$14:$I$53) + SUMIF('Soca Draw'!$C$4:$C$31,"="&$D25,'Soca Draw'!$D$4:$D$31) -> 0 | J25: =SUMIF($G$14:$G$53,"="&D25,$J$14:$J$53) + SUMIF('Soca Draw'!$C$4:$C$31,"="&$D25,'Soca Draw'!$E$4:$E$31) -> 0 | K25: =SUMIF($G$14:$G$53,"="&D25,$K$14:$K$53) + SUMIF('Soca Draw'!$C$4:$C$31,"="&$D25,'Soca Draw'!$F$4:$F$31) -> 0 | L25: =SUM(I25:K25) -> 0 | M25: =IFERROR((L25/N25), 0) -> 0 | N25: =IFERROR(VLOOKUP(F25, 'Distro Database'!$C$5:$D$200, 2, 0), IFERROR(VLOOKUP(G25, D15:N24, 5, 0), 0)) -> 0 | O25: =N25/3 -> 0
C26: PD23 | D26: =CONCATENATE(C26," - ",F26) -> PD23 - | I26: =SUMIF($G$14:$G$53,"="&D26,$I$14:$I$53) + SUMIF('Soca Draw'!$C$4:$C$31,"="&$D26,'Soca Draw'!$D$4:$D$31) -> 0 | J26: =SUMIF($G$14:$G$53,"="&D26,$J$14:$J$53) + SUMIF('Soca Draw'!$C$4:$C$31,"="&$D26,'Soca Draw'!$E$4:$E$31) -> 0 | K26: =SUMIF($G$14:$G$53,"="&D26,$K$14:$K$53) + SUMIF('Soca Draw'!$C$4:$C$31,"="&$D26,'Soca Draw'!$F$4:$F$31) -> 0 | L26: =SUM(I26:K26) -> 0 | M26: =IFERROR((L26/N26), 0) -> 0 | N26: =IFERROR(VLOOKUP(F26, 'Distro Database'!$C$5:$D$200, 2, 0), IFERROR(VLOOKUP(G26, D16:N25, 5, 0), 0)) -> 0 | O26: =N26/3 -> 0
C27: PD24 | D27: =CONCATENATE(C27," - ",F27) -> PD24 - | I27: =SUMIF($G$14:$G$53,"="&D27,$I$14:$I$53) + SUMIF('Soca Draw'!$C$4:$C$31,"="&$D27,'Soca Draw'!$D$4:$D$31) -> 0 | J27: =SUMIF($G$14:$G$53,"="&D27,$J$14:$J$53) + SUMIF('Soca Draw'!$C$4:$C$31,"="&$D27,'Soca Draw'!$E$4:$E$31) -> 0 | K27: =SUMIF($G$14:$G$53,"="&D27,$K$14:$K$53) + SUMIF('Soca Draw'!$C$4:$C$31,"="&$D27,'Soca Draw'!$F$4:$F$31) -> 0 | L27: =SUM(I27:K27) -> 0 | M27: =IFERROR((L27/N27), 0) -> 0 | N27: =IFERROR(VLOOKUP(F27, 'Distro Database'!$C$5:$D$200, 2, 0), IFERROR(VLOOKUP(G27, D17:N26, 5, 0), 0)) -> 0 | O27: =N27/3 -> 0
C28: PD25 | D28: =CONCATENATE(C28," - ",F28) -> PD25 - | I28: =SUMIF($G$14:$G$53,"="&D28,$I$14:$I$53) + SUMIF('Soca Draw'!$C$4:$C$31,"="&$D28,'Soca Draw'!$D$4:$D$31) -> 0 | J28: =SUMIF($G$14:$G$53,"="&D28,$J$14:$J$53) + SUMIF('Soca Draw'!$C$4:$C$31,"="&$D28,'Soca Draw'!$E$4:$E$31) -> 0 | K28: =SUMIF($G$14:$G$53,"="&D28,$K$14:$K$53) + SUMIF('Soca Draw'!$C$4:$C$31,"="&$D28,'Soca Draw'!$F$4:$F$31) -> 0 | L28: =SUM(I28:K28) -> 0 | M28: =IFERROR((L28/N28), 0) -> 0 | N28: =IFERROR(VLOOKUP(F28, 'Distro Database'!$C$5:$D$200, 2, 0), IFERROR(VLOOKUP(G28, D18:N27, 5, 0), 0)) -> 0 | O28: =N28/3 -> 0
C29: PD26 | D29: =CONCATENATE(C29," - ",F29) -> PD26 - | I29: =SUMIF($G$14:$G$53,"="&D29,$I$14:$I$53) + SUMIF('Soca Draw'!$C$4:$C$31,"="&$D29,'Soca Draw'!$D$4:$D$31) -> 0 | J29: =SUMIF($G$14:$G$53,"="&D29,$J$14:$J$53) + SUMIF('Soca Draw'!$C$4:$C$31,"="&$D29,'Soca Draw'!$E$4:$E$31) -> 0 | K29: =SUMIF($G$14:$G$53,"="&D29,$K$14:$K$53) + SUMIF('Soca Draw'!$C$4:$C$31,"="&$D29,'Soca Draw'!$F$4:$F$31) -> 0 | L29: =SUM(I29:K29) -> 0 | M29: =IFERROR((L29/N29), 0) -> 0 | N29: =IFERROR(VLOOKUP(F29, 'Distro Database'!$C$5:$D$200, 2, 0), IFERROR(VLOOKUP(G29, D19:N28, 5, 0), 0)) -> 0 | O29: =N29/3 -> 0
C30: PD27 | D30: =CONCATENATE(C30," - ",F30) -> PD27 - | I30: =SUMIF($G$14:$G$53,"="&D30,$I$14:$I$53) + SUMIF('Soca Draw'!$C$4:$C$31,"="&$D30,'Soca Draw'!$D$4:$D$31) -> 0 | J30: =SUMIF($G$14:$G$53,"="&D30,$J$14:$J$53) + SUMIF('Soca Draw'!$C$4:$C$31,"="&$D30,'Soca Draw'!$E$4:$E$31) -> 0 | K30: =SUMIF($G$14:$G$53,"="&D30,$K$14:$K$53) + SUMIF('Soca Draw'!$C$4:$C$31,"="&$D30,'Soca Draw'!$F$4:$F$31) -> 0 | L30: =SUM(I30:K30) -> 0 | M30: =IFERROR((L30/N30), 0) -> 0 | N30: =IFERROR(VLOOKUP(F30, 'Distro Database'!$C$5:$D$200, 2, 0), IFERROR(VLOOKUP(G30, D20:N29, 5, 0), 0)) -> 0 | O30: =N30/3 -> 0
C31: PD28 | D31: =CONCATENATE(C31," - ",F31) -> PD28 - | I31: =SUMIF($G$14:$G$53,"="&D31,$I$14:$I$53) + SUMIF('Soca Draw'!$C$4:$C$31,"="&$D31,'Soca Draw'!$D$4:$D$31) -> 0 | J31: =SUMIF($G$14:$G$53,"="&D31,$J$14:$J$53) + SUMIF('Soca Draw'!$C$4:$C$31,"="&$D31,'Soca Draw'!$E$4:$E$31) -> 0 | K31: =SUMIF($G$14:$G$53,"="&D31,$K$14:$K$53) + SUMIF('Soca Draw'!$C$4:$C$31,"="&$D31,'Soca Draw'!$F$4:$F$31) -> 0 | L31: =SUM(I31:K31) -> 0 | M31: =IFERROR((L31/N31), 0) -> 0 | N31: =IFERROR(VLOOKUP(F31, 'Distro Database'!$C$5:$D$200, 2, 0), IFERROR(VLOOKUP(G31, D21:N30, 5, 0), 0)) -> 0 | O31: =N31/3 -> 0
C32: PD29 | D32: =CONCATENATE(C32," - ",F32) -> PD29 - | I32: =SUMIF($G$14:$G$53,"="&D32,$I$14:$I$53) + SUMIF('Soca Draw'!$C$4:$C$31,"="&$D32,'Soca Draw'!$D$4:$D$31) -> 0 | J32: =SUMIF($G$14:$G$53,"="&D32,$J$14:$J$53) + SUMIF('Soca Draw'!$C$4:$C$31,"="&$D32,'Soca Draw'!$E$4:$E$31) -> 0 | K32: =SUMIF($G$14:$G$53,"="&D32,$K$14:$K$53) + SUMIF('Soca Draw'!$C$4:$C$31,"="&$D32,'Soca Draw'!$F$4:$F$31) -> 0 | L32: =SUM(I32:K32) -> 0 | M32: =IFERROR((L32/N32), 0) -> 0 | N32: =IFERROR(VLOOKUP(F32, 'Distro Database'!$C$5:$D$200, 2, 0), IFERROR(VLOOKUP(G32, D22:N31, 5, 0), 0)) -> 0 | O32: =N32/3 -> 0
C33: PD30 | D33: =CONCATENATE(C33," - ",F33) -> PD30 - | I33: =SUMIF($G$14:$G$53,"="&D33,$I$14:$I$53) + SUMIF('Soca Draw'!$C$4:$C$31,"="&$D33,'Soca Draw'!$D$4:$D$31) -> 0 | J33: =SUMIF($G$14:$G$53,"="&D33,$J$14:$J$53) + SUMIF('Soca Draw'!$C$4:$C$31,"="&$D33,'Soca Draw'!$E$4:$E$31) -> 0 | K33: =SUMIF($G$14:$G$53,"="&D33,$K$14:$K$53) + SUMIF('Soca Draw'!$C$4:$C$31,"="&$D33,'Soca Draw'!$F$4:$F$31) -> 0 | L33: =SUM(I33:K33) -> 0 | M33: =IFERROR((L33/N33), 0) -> 0 | N33: =IFERROR(VLOOKUP(F33, 'Distro Database'!$C$5:$D$200, 2, 0), IFERROR(VLOOKUP(G33, D23:N32, 5, 0), 0)) -> 0 | O33: =N33/3 -> 0
B34: Distro 3 | C34: PD31 | D34: =CONCATENATE(C34," - ",F34) -> PD31 - | I34: =SUMIF($G$14:$G$53,"="&D34,$I$14:$I$53) + SUMIF('Soca Draw'!$C$4:$C$31,"="&$D34,'Soca Draw'!$D$4:$D$31) -> 0 | J34: =SUMIF($G$14:$G$53,"="&D34,$J$14:$J$53) + SUMIF('Soca Draw'!$C$4:$C$31,"="&$D34,'Soca Draw'!$E$4:$E$31) -> 0 | K34: =SUMIF($G$14:$G$53,"="&D34,$K$14:$K$53) + SUMIF('Soca Draw'!$C$4:$C$31,"="&$D34,'Soca Draw'!$F$4:$F$31) -> 0 | L34: =SUM(I34:K34) -> 0 | M34: =IFERROR((L34/N34), 0) -> 0 | N34: =IFERROR(VLOOKUP(F34, 'Distro Database'!$C$5:$D$200, 2, 0), IFERROR(VLOOKUP(G34, D24:N33, 5, 0), 0)) -> 0 | O34: =N34/3 -> 0
C35: PD32 | D35: =CONCATENATE(C35," - ",F35) -> PD32 - | I35: =SUMIF($G$14:$G$53,"="&D35,$I$14:$I$53) + SUMIF('Soca Draw'!$C$4:$C$31,"="&$D35,'Soca Draw'!$D$4:$D$31) -> 0 | J35: =SUMIF($G$14:$G$53,"="&D35,$J$14:$J$53) + SUMIF('Soca Draw'!$C$4:$C$31,"="&$D35,'Soca Draw'!$E$4:$E$31) -> 0 | K35: =SUMIF($G$14:$G$53,"="&D35,$K$14:$K$53) + SUMIF('Soca Draw'!$C$4:$C$31,"="&$D35,'Soca Draw'!$F$4:$F$31) -> 0 | L35: =SUM(I35:K35) -> 0 | M35: =IFERROR((L35/N35), 0) -> 0 | N35: =IFERROR(VLOOKUP(F35, 'Distro Database'!$C$5:$D$200, 2, 0), IFERROR(VLOOKUP(G35, D25:N34, 5, 0), 0)) -> 0 | O35: =N35/3 -> 0
C36: PD33 | D36: =CONCATENATE(C36," - ",F36) -> PD33 - | I36: =SUMIF($G$14:$G$53,"="&D36,$I$14:$I$53) + SUMIF('Soca Draw'!$C$4:$C$31,"="&$D36,'Soca Draw'!$D$4:$D$31) -> 0 | J36: =SUMIF($G$14:$G$53,"="&D36,$J$14:$J$53) + SUMIF('Soca Draw'!$C$4:$C$31,"="&$D36,'Soca Draw'!$E$4:$E$31) -> 0 | K36: =SUMIF($G$14:$G$53,"="&D36,$K$14:$K$53) + SUMIF('Soca Draw'!$C$4:$C$31,"="&$D36,'Soca Draw'!$F$4:$F$31) -> 0 | L36: =SUM(I36:K36) -> 0 | M36: =IFERROR((L36/N36), 0) -> 0 | N36: =IFERROR(VLOOKUP(F36, 'Distro Database'!$C$5:$D$200, 2, 0), IFERROR(VLOOKUP(G36, D26:N35, 5, 0), 0)) -> 0 | O36: =N36/3 -> 0
C37: PD34 | D37: =CONCATENATE(C37," - ",F37) -> PD34 - | I37: =SUMIF($G$14:$G$53,"="&D37,$I$14:$I$53) + SUMIF('Soca Draw'!$C$4:$C$31,"="&$D37,'Soca Draw'!$D$4:$D$31) -> 0 | J37: =SUMIF($G$14:$G$53,"="&D37,$J$14:$J$53) + SUMIF('Soca Draw'!$C$4:$C$31,"="&$D37,'Soca Draw'!$E$4:$E$31) -> 0 | K37: =SUMIF($G$14:$G$53,"="&D37,$K$14:$K$53) + SUMIF('Soca Draw'!$C$4:$C$31,"="&$D37,'Soca Draw'!$F$4:$F$31) -> 0 | L37: =SUM(I37:K37) -> 0 | M37: =IFERROR((L37/N37), 0) -> 0 | N37: =IFERROR(VLOOKUP(F37, 'Distro Database'!$C$5:$D$200, 2, 0), IFERROR(VLOOKUP(G37, D27:N36, 5, 0), 0)) -> 0 | O37: =N37/3 -> 0
C38: PD35 | D38: =CONCATENATE(C38," - ",F38) -> PD35 - | I38: =SUMIF($G$14:$G$53,"="&D38,$I$14:$I$53) + SUMIF('Soca Draw'!$C$4:$C$31,"="&$D38,'Soca Draw'!$D$4:$D$31) -> 0 | J38: =SUMIF($G$14:$G$53,"="&D38,$J$14:$J$53) + SUMIF('Soca Draw'!$C$4:$C$31,"="&$D38,'Soca Draw'!$E$4:$E$31) -> 0 | K38: =SUMIF($G$14:$G$53,"="&D38,$K$14:$K$53) + SUMIF('Soca Draw'!$C$4:$C$31,"="&$D38,'Soca Draw'!$F$4:$F$31) -> 0 | L38: =SUM(I38:K38) -> 0 | M38: =IFERROR((L38/N38), 0) -> 0 | N38: =IFERROR(VLOOKUP(F38, 'Distro Database'!$C$5:$D$200, 2, 0), IFERROR(VLOOKUP(G38, D28:N37, 5, 0), 0)) -> 0 | O38: =N38/3 -> 0
C39: PD36 | D39: =CONCATENATE(C39," - ",F39) -> PD36 - | I39: =SUMIF($G$14:$G$53,"="&D39,$I$14:$I$53) + SUMIF('Soca Draw'!$C$4:$C$31,"="&$D39,'Soca Draw'!$D$4:$D$31) -> 0 | J39: =SUMIF($G$14:$G$53,"="&D39,$J$14:$J$53) + SUMIF('Soca Draw'!$C$4:$C$31,"="&$D39,'Soca Draw'!$E$4:$E$31) -> 0 | K39: =SUMIF($G$14:$G$53,"="&D39,$K$14:$K$53) + SUMIF('Soca Draw'!$C$4:$C$31,"="&$D39,'Soca Draw'!$F$4:$F$31) -> 0 | L39: =SUM(I39:K39) -> 0 | M39: =IFERROR((L39/N39), 0) -> 0 | N39: =IFERROR(VLOOKUP(F39, 'Distro Database'!$C$5:$D$200, 2, 0), IFERROR(VLOOKUP(G39, D29:N38, 5, 0), 0)) -> 0 | O39: =N39/3 -> 0
C40: PD37 | D40: =CONCATENATE(C40," - ",F40) -> PD37 - | I40: =SUMIF($G$14:$G$53,"="&D40,$I$14:$I$53) + SUMIF('Soca Draw'!$C$4:$C$31,"="&$D40,'Soca Draw'!$D$4:$D$31) -> 0 | J40: =SUMIF($G$14:$G$53,"="&D40,$J$14:$J$53) + SUMIF('Soca Draw'!$C$4:$C$31,"="&$D40,'Soca Draw'!$E$4:$E$31) -> 0 | K40: =SUMIF($G$14:$G$53,"="&D40,$K$14:$K$53) + SUMIF('Soca Draw'!$C$4:$C$31,"="&$D40,'Soca Draw'!$F$4:$F$31) -> 0 | L40: =SUM(I40:K40) -> 0 | M40: =IFERROR((L40/N40), 0) -> 0 | N40: =IFERROR(VLOOKUP(F40, 'Distro Database'!$C$5:$D$200, 2, 0), IFERROR(VLOOKUP(G40, D30:N39, 5, 0), 0)) -> 0 | O40: =N40/3 -> 0
C41: PD38 | D41: =CONCATENATE(C41," - ",F41) -> PD38 - | I41: =SUMIF($G$14:$G$53,"="&D41,$I$14:$I$53) + SUMIF('Soca Draw'!$C$4:$C$31,"="&$D41,'Soca Draw'!$D$4:$D$31) -> 0 | J41: =SUMIF($G$14:$G$53,"="&D41,$J$14:$J$53) + SUMIF('Soca Draw'!$C$4:$C$31,"="&$D41,'Soca Draw'!$E$4:$E$31) -> 0 | K41: =SUMIF($G$14:$G$53,"="&D41,$K$14:$K$53) + SUMIF('Soca Draw'!$C$4:$C$31,"="&$D41,'Soca Draw'!$F$4:$F$31) -> 0 | L41: =SUM(I41:K41) -> 0 | M41: =IFERROR((L41/N41), 0) -> 0 | N41: =IFERROR(VLOOKUP(F41, 'Distro Database'!$C$5:$D$200, 2, 0), IFERROR(VLOOKUP(G41, D31:N40, 5, 0), 0)) -> 0 | O41: =N41/3 -> 0
...

Sheet Gear Count
E1: Gear Count
C2: LX 1 | D2: LX 2 | E2: LX 3 | F2: LX 4 | G2: LX 5 | H2: LX 6 | I2: LX 7 | J2: LX 8 | K2: LX 9 | L2: LX 10 | M2: LX 11 | N2: LX 12 | O2: LX 13 | P2: LX 14 | Q2: LX 15 | R2: LX 16 | S2: LX 17 | T2: LX 18 | U2: LX 19 | V2: LX 20 | W2: LX 21 | X2: System | Y2: Spare | Z2: Sum
B3: Lamper | C3: FALSE | D3: FALSE | E3: FALSE | F3: FALSE | G3: FALSE | H3: FALSE | I3: FALSE | J3: FALSE | K3: FALSE | L3: FALSE | M3: FALSE | N3: FALSE | O3: FALSE | P3: FALSE | Q3: FALSE | R3: FALSE | S3: FALSE | T3: FALSE | U3: FALSE | V3: FALSE | W3: FALSE | X3: FALSE | Y3: FALSE | AA3: =B3 -> Lamper
B4: Aura XB | Z4: =SUM(C4:Y4) -> 0 | AA4: =B4 -> Aura XB
B5: Aura XIP | Z5: =SUM(C5:Y5) -> 0 | AA5: =B5 -> Aura XIP
B6: R2X | Z6: =SUM(C6:Y6) -> 0 | AA6: =B6 -> R2X
B7: R1 BW | Z7: =SUM(C7:Y7) -> 0 | AA7: =B7 -> R1 BW
B8: MH7 | Z8: =SUM(C8:Y8) -> 0 | AA8: =B8 -> MH7
B9: Mythos 2 | Z9: =SUM(C9:Y9) -> 0 | AA9: =B9 -> Mythos 2
B10: Diablo S | Z10: =SUM(C10:Y10) -> 0 | AA10: =B10 -> Diablo S
B11: Mac Ultra P | Z11: =SUM(C11:Y11) -> 0 | AA11: =B11 -> Mac Ultra P
B12: XLED | AA12: =B12 -> XLED
B13: XBAR | AA13: =B13 -> XBAR
B14: Magic Panel | AA14: =B14 -> Magic Panel
B15: Minipanel FX | AA15: =B15 -> Minipanel FX
B16: DMX | C16: FALSE | D16: FALSE | E16: FALSE | F16: FALSE | G16: FALSE | H16: FALSE | I16: FALSE | J16: FALSE | K16: FALSE | L16: FALSE | M16: FALSE | N16: FALSE | O16: FALSE | P16: FALSE | Q16: FALSE | R16: FALSE | S16: FALSE | T16: FALSE | U16: FALSE | V16: FALSE | W16: FALSE | X16: FALSE | Y16: FALSE | Z16: =SUM(C16:Y16) -> 0 | AA16: =B16 -> DMX
B17: 0.5m | Z17: =SUM(C17:Y17) -> 0 | AA17: =B17 -> 0.5m
B18: 1.5m | Z18: =SUM(C18:Y18) -> 0 | AA18: =B18 -> 1.5m
B19: 3m | Z19: =SUM(C19:Y19) -> 0 | AA19: =B19 -> 3m
B20: 6m | Z20: =SUM(C20:Y20) -> 0 | AA20: =B20 -> 6m
B21: 9m | Z21: =SUM(C21:Y21) -> 0 | AA21: =B21 -> 9m
B22: 12m | Z22: =SUM(C22:Y22) -> 0 | AA22: =B22 -> 12m
B23: 24m | Z23: =SUM(C23:Y23) -> 0 | AA23: =B23 -> 24m
Z24: =SUM(C24:Y24) -> 0
B25: Skjøt | C25: FALSE | D25: FALSE | E25: FALSE | F25: FALSE | G25: FALSE | H25: FALSE | I25: FALSE | J25: FALSE | K25: FALSE | L25: FALSE | M25: FALSE | N25: FALSE | O25: FALSE | P25: FALSE | Q25: FALSE | R25: FALSE | S25: FALSE | T25: FALSE | U25: FALSE | V25: FALSE | W25: FALSE | X25: FALSE | Y25: FALSE | Z25: =SUM(C25:Y25) -> 0 | AA25: =B25 -> Skjøt
B26: 6-veis Padde | Z26: =SUM(C26:Y26) -> 0 | AA26: =B26 -> 6-veis Padde
B27: 0.5m | Z27: =SUM(C27:Y27) -> 0 | AA27: =B27 -> 0.5m
B28: 1.5m | Z28: =SUM(C28:Y28) -> 0 | AA28: =B28 -> 1.5m
B29: 2m | Z29: =SUM(C29:Y29) -> 0 | AA29: =B29 -> 2m
B30: 3m | Z30: =SUM(C30:Y30) -> 0 | AA30: =B30 -> 3m
B31: 5m | Z31: =SUM(C31:Y31) -> 0 | AA31: =B31 -> 5m
B32: 6m | Z32: =SUM(C32:Y32) -> 0 | AA32: =B32 -> 6m
B33: 9m | Z33: =SUM(C33:Y33) -> 0 | AA33: =B33 -> 9m
B34: 12m | Z34: =SUM(C34:Y34) -> 0 | AA34: =B34 -> 12m
B35: 15m | Z35: =SUM(C35:Y35) -> 0 | AA35: =B35 -> 15m
B36: 20m | Z36: =SUM(C36:Y36) -> 0 | AA36: =B36 -> 20m
B37: 25m | Z37: =SUM(C37:Y37) -> 0 | AA37: =B37 -> 25m
B38: Hybrid T1 | C38: FALSE | D38: FALSE | E38: FALSE | F38: FALSE | G38: FALSE | H38: FALSE | I38: FALSE | J38: FALSE | K38: FALSE | L38: FALSE | M38: FALSE | N38: FALSE | O38: FALSE | P38: FALSE | Q38: FALSE | R38: FALSE | S38: FALSE | T38: FALSE | U38: FALSE | V38: FALSE | W38: FALSE | X38: FALSE | Y38: FALSE | Z38: =SUM(C38:Y38) -> 0 | AA38: =B38 -> Hybrid T1
B39: 1m | Z39: =SUM(C39:Y39) -> 0 | AA39: =B39 -> 1m
B40: 1.5m | Z40: =SUM(C40:Y40) -> 0 | AA40: =B40 -> 1.5m
...

Sheet Shoppinglist
E2: Shopping List
C4: Powerfeed (no name = Soca) | D4: Socapex in Truss | E4: Signal Feed | F4: Schuko Cable | G4: DMX Cable | H4: Hybrid Cable | I4: SneakSnake | J4: Ethercon | K4: Others | L4: Power Patch | M4: Signal Patch
B5: LX 1
B6: LX 2
B7: LX 3
B8: LX 4
B9: LX 5
B10: LX 6
B11: LX 7
B12: LX 8
B13: LX 9
B14: LX 10
B15: LX 11
B16: LX 12
... B34: LX 30

Sheet LK Patch
D2: =getfilename() -> #NAME?
D3: LK Patch
B5: LK# | C5: 1 | D5: Name here
B6: In/output | C6: 1 | D6: In/output | E6: 2 | F6: In/output | G6: 5 | H6: In/output | I6: 6 | J6: In/output | K6: 9 | L6: In/output | M6: 10
B7: Universe | D7: Universe | F7: Universe | H7: Universe | J7: Universe | L7: Universe
B8: Fix. Type | D8: Fix. Type | F8: Fix. Type | H8: Fix. Type | J8: Fix. Type | L8: Fix. Type
B9: Pos. | D9: Pos. | F9: Pos. | H9: Pos. | J9: Pos. | L9: Pos.
B10: In/output | C10: 3 | D10: In/output | E10: 4 | F10: In/output | G10: 7 | H10: In/output | I10: 8 | J10: In/output | K10: 11 | L10: In/output | M10: 12
B11: Universe | D11: Universe | F11: Universe | H11: Universe | J11: Universe | L11: Universe
B12: Fix. Type | D12: Fix. Type | F12: Fix. Type | H12: Fix. Type | J12: Fix. Type | L12: Fix. Type
B13: Pos. | D13: Pos. | F13: Pos. | H13: Pos. | J13: Pos. | L13: Pos.
B15: LK# | C15: 2 | D15: Name here
B16: In/output | C16: 1 | D16: In/output | E16: 2 | F16: In/output | G16: 5 | H16: In/output | I16: 6 | J16: In/output | K16: 9 | L16: In/output | M16: 10
B17: Universe | D17: Universe | F17: Universe | H17: Universe | J17: Universe | L17: Universe
B18: Fix. Type | D18: Fix. Type | F18: Fix. Type | H18: Fix. Type | J18: Fix. Type | L18: Fix. Type
B19: Pos. | D19: Pos. | F19: Pos. | H19: Pos. | J19: Pos. | L19: Pos.
B20: In/output | C20: 3 | D20: In/output | E20: 4 | F20: In/output | G20: 7 | H20: In/output | I20: 8 | J20: In/output | K20: 11 | L20: In/output | M20: 12
B21: Universe | D21: Universe | F21: Universe | H21: Universe | J21: Universe | L21: Universe
B22: Fix. Type | D22: Fix. Type | F22: Fix. Type | H22: Fix. Type | J22: Fix. Type | L22: Fix. Type
B23: Pos. | D23: Pos. | F23: Pos. | H23: Pos. | J23: Pos. | L23: Pos.
B25: LK# | C25: 3 | D25: Name here
B26: In/output | C26: 1 | D26: In/output | E26: 2 | F26: In/output | G26: 5 | H26: In/output | I26: 6 | J26: In/output | K26: 9 | L26: In/output | M26: 10
B27: Universe | D27: Universe | F27: Universe | H27: Universe | J27: Universe | L27: Universe
B28: Fix. Type | D28: Fix. Type | F28: Fix. Type | H28: Fix. Type | J28: Fix. Type | L28: Fix. Type
B29: Pos. | D29: Pos. | F29: Pos. | H29: Pos. | J29: Pos. | L29: Pos.
B30: In/output | C30: 3 | D30: In/output | E30: 4 | F30: In/output | G30: 7 | H30: In/output | I30: 8 | J30: In/output | K30: 11 | L30: In/output | M30: 12
B31: Universe | D31: Universe | F31: Universe | H31: Universe | J31: Universe | L31: Universe
B32: Fix. Type | D32: Fix. Type | F32: Fix. Type | H32: Fix. Type | J32: Fix. Type | L32: Fix. Type
B33: Pos. | D33: Pos. | F33: Pos. | H33: Pos. | J33: Pos. | L33: Pos.

Sheet SneakSnake Patch
D2: =getfilename() -> #NAME?
D3: SneakSnake Patch
B5: SS# | C5: 1 | D5: Name here | K5: SS# | L5: 2 | M5: Name here
B6: In/output | C6: 1 | D6: In/output | E6: 2 | F6: In/output | G6: 3 | H6: In/output | I6: 4 | K6: In/output | L6: 1 | M6: In/output | N6: 2 | O6: In/output | P6: 3 | Q6: In/output | R6: 4
B7: Universe | D7: Universe | F7: Universe | H7: Universe | K7: Universe | M7: Universe | O7: Universe | Q7: Universe
B8: Fix. Type | D8: Fix. Type | F8: Fix. Type | H8: Fix. Type | K8: Fix. Type | M8: Fix. Type | O8: Fix. Type | Q8: Fix. Type
B9: Pos. | D9: Pos. | F9: Pos. | H9: Pos. | K9: Pos. | M9: Pos. | O9: Pos. | Q9: Pos.
B11: SS# | C11: 3 | D11: Name here | K11: SS# | L11: 4 | M11: Name here
B12: In/output | C12: 1 | D12: In/output | E12: 2 | F12: In/output | G12: 3 | H12: In/output | I12: 4 | K12: In/output | L12: 1 | M12: In/output | N12: 2 | O12: In/output | P12: 3 | Q12: In/output | R12: 4
B13: Universe | D13: Universe | F13: Universe | H13: Universe | K13: Universe | M13: Universe | O13: Universe | Q13: Universe
B14: Fix. Type | D14: Fix. Type | F14: Fix. Type | H14: Fix. Type | K14: Fix. Type | M14: Fix. Type | O14: Fix. Type | Q14: Fix. Type
B15: Pos. | D15: Pos. | F15: Pos. | H15: Pos. | K15: Pos. | M15: Pos. | O15: Pos. | Q15: Pos.
B17: SS# | C17: 5 | D17: Name here | K17: SS# | L17: 6 | M17: Name here
B18: In/output | C18: 1 | D18: In/output | E18: 2 | F18: In/output | G18: 3 | H18: In/output | I18: 4 | K18: In/output | L18: 1 | M18: In/output | N18: 2 | O18: In/output | P18: 3 | Q18: In/output | R18: 4
B19: Universe | D19: Universe | F19: Universe | H19: Universe | K19: Universe | M19: Universe | O19: Universe | Q19: Universe
B20: Fix. Type | D20: Fix. Type | F20: Fix. Type | H20: Fix. Type | K20: Fix. Type | M20: Fix. Type | O20: Fix. Type | Q20: Fix. Type
B21: Pos. | D21: Pos. | F21: Pos. | H21: Pos. | K21: Pos. | M21: Pos. | O21: Pos. | Q21: Pos.
B23: SS# | C23: 7 | D23: Name here | K23: SS# | L23: 8 | M23: Name here
B24: In/output | C24: 1 | D24: In/output | E24: 2 | F24: In/output | G24: 3 | H24: In/output | I24: 4 | K24: In/output | L24: 1 | M24: In/output | N24: 2 | O24: In/output | P24: 3 | Q24: In/output | R24: 4
B25: Universe | D25: Universe | F25: Universe | H25: Universe | K25: Universe | M25: Universe | O25: Universe | Q25: Universe
B26: Fix. Type | D26: Fix. Type | F26: Fix. Type | H26: Fix. Type | K26: Fix. Type | M26: Fix. Type | O26: Fix. Type | Q26: Fix. Type
B27: Pos. | D27: Pos. | F27: Pos. | H27: Pos. | K27: Pos. | M27: Pos. | O27: Pos. | Q27: Pos.
B29: SS# | C29: 9 | D29: Name here | K29: SS# | L29: 10 | M29: Name here
B30: In/output | C30: 1 | D30: In/output | E30: 2 | F30: In/output | G30: 3 | H30: In/output | I30: 4 | K30: In/output | L30: 1 | M30: In/output | N30: 2 | O30: In/output | P30: 3 | Q30: In/output | R30: 4
B31: Universe | D31: Universe | F31: Universe | H31: Universe | K31: Universe | M31: Universe | O31: Universe | Q31: Universe
B32: Fix. Type | D32: Fix. Type | F32: Fix. Type | H32: Fix. Type | K32: Fix. Type | M32: Fix. Type | O32: Fix. Type | Q32: Fix. Type
B33: Pos. | D33: Pos. | F33: Pos. | H33: Pos. | K33: Pos. | M33: Pos. | O33: Pos. | Q33: Pos.
B35: SS# | C35: 11 | D35: Name here | K35: SS# | L35: 12 | M35: Name here
B36: In/output | C36: 1 | D36: In/output | E36: 2 | F36: In/output | G36: 3 | H36: In/output | I36: 4 | K36: In/output | L36: 1 | M36: In/output | N36: 2 | O36: In/output | P36: 3 | Q36: In/output | R36: 4
B37: Universe | D37: Universe | F37: Universe | H37: Universe | K37: Universe | M37: Universe | O37: Universe | Q37: Universe
B38: Fix. Type | D38: Fix. Type | F38: Fix. Type | H38: Fix. Type | K38: Fix. Type | M38: Fix. Type | O38: Fix. Type | Q38: Fix. Type
B39: Pos. | D39: Pos. | F39: Pos. | H39: Pos. | K39: Pos. | M39: Pos. | O39: Pos. | Q39: Pos.

Sheet Node Patch
D2: =getfilename() -> #NAME?
D3: Node Patch
B5: Node# | C5: 1 | D5: Luminode12 | G5: 192.168.x.x
C6: Port 1 | D6: Port 2 | E6: Port 3 | F6: Port 4 | G6: Port 5 | H6: Port 6 | I6: Port 7 | J6: Port 8 | K6: Port 9 | L6: Port 10 | M6: Port 11 | N6: Port 12
A7: =IF($C7="Disabled", 1, 0) -> 0 | B7: Netverk | C7: sACN | D7: sACN | E7: sACN | F7: sACN | G7: sACN | H7: sACN | I7: sACN | J7: sACN | K7: sACN | L7: sACN | M7: sACN | N7: sACN
B8: In/output | C8: Output | D8: Output | E8: Output | F8: Output | G8: Output | H8: Output | I8: Output | J8: Output | K8: Output | L8: Output | M8: Output | N8: Output
B9: Universe
B10: Goes to?
B12: Node# | C12: 2 | D12: Luminode12 | G12: 192.168.x.x
C13: Port 1 | D13: Port 2 | E13: Port 3 | F13: Port 4 | G13: Port 5 | H13: Port 6 | I13: Port 7 | J13: Port 8 | K13: Port 9 | L13: Port 10 | M13: Port 11 | N13: Port 12
B14: Netverk | C14: Disabled | D14: Disabled | E14: Disabled | F14: Disabled | G14: Disabled | H14: Disabled | I14: Disabled | J14: Disabled | K14: Disabled | L14: Disabled | M14: Disabled | N14: Disabled
B15: In/output
B16: Universe
B17: Goes to?
B19: Node# | C19: 3 | D19: Luminode12 | G19: 192.168.x.x
C20: Port 1 | D20: Port 2 | E20: Port 3 | F20: Port 4 | G20: Port 5 | H20: Port 6 | I20: Port 7 | J20: Port 8 | K20: Port 9 | L20: Port 10 | M20: Port 11 | N20: Port 12
B21: Netverk | C21: Disabled | D21: Disabled | E21: Disabled | F21: Disabled | G21: Disabled | H21: Disabled | I21: Disabled | J21: Disabled | K21: Disabled | L21: Disabled | M21: Disabled | N21: Disabled
B22: In/output
B23: Universe
B24: Goes to?
B26: Node# | C26: 4 | D26: Luminode12 | G26: 192.168.x.x
C27: Port 1 | D27: Port 2 | E27: Port 3 | F27: Port 4 | G27: Port 5 | H27: Port 6 | I27: Port 7 | J27: Port 8 | K27: Port 9 | L27: Port 10 | M27: Port 11 | N27: Port 12
B28: Netverk | C28: Disabled | D28: Disabled | E28: Disabled | F28: Disabled | G28: Disabled | H28: Disabled | I28: Disabled | J28: Disabled | K28: Disabled | L28: Disabled | M28: Disabled | N28: Disabled
B29: In/output
B30: Universe
B31: Goes to?

Sheet Unit Database
B2: Unit Database
B4: Manufacturer | C4: Model | D4: Watt | E4: Ampere | F4: Max Link | G4: Weight
B5: Martin Lighting | C5: Mac Aura XB | D5: 400 | E5: 1.7 | G5: 6.5
B6: Martin Lighting | C6: Mac Aura | D6: 260 | E6: 1.1 | G6: 5.6
B7: Martin Lighting | C7: Mac Aura XIP | D7: 340 | E7: 1.8 | G7: 8.95
B8: Martin Lighting | C8: Rush MH7 | D8: 400 | E8: 1.7 | G8: 24
B9: Martin Lighting | C9: Mac Ultra Performance | D9: 1450 | E9: 6.7 | G9: 44
B10: Martin Lighting | C10: Quantum Profile | D10: 750 | E10: 2.5
B11: Martin Lighting | C11: Quantum Wash | D11: 1020 | E11: 3.8
B12: Martin Lighting | C12: Mac Aura PXL | D12: 560 | E12: 2.8
B13: Martin Lighting | C13: Mac Allure Profile | D13: 500 | E13: 2.1
B14: Martin Lighting | C14: Mac Viper Profile | D14: 1200 | E14: 5.2
B15: Martin Lighting | C15: Mac Viper Performance | D15: 1200 | E15: 5.2
B16: Martin Lighting | C16: Mac Encore Performance | D16: 600 | E16: 2.6
B17: Martin Lighting | C17: VDO Atomic Dot | D17: 55 | E17: 0.23
B18: Martin Lighting | C18: VDO Atomic Bold | D18: 400 | E18: 1.59
B19: Martin Lighting | C19: Rush Par 2 | D19: 151 | E19: 0.7
B20: Martin Lighting | C20: Powerport 1500 | D20: 1540 | E20: 6.56
B21: Martin Lighting | C21: P3-300 | D21: 0 | E21: 0
... B24: Martin Lighting | C24: Face 5 HB | D24: 191 | E24: 1.94
B25: Martin Lighting | C25: Atomic 3000 | D25: 3000 | E25: 8 | G25: 7.5
B26: Chauvet | C26: R1 BeamWash | D26: 284 | E26: 1.23 | F26: 11
